Workbook

Sheet GPay-UPI Summary
A1: GPay / UPI — Incoming & Outgoing, Date-wise by Account
A2: UPI-tagged transactions only (excludes NEFT/IMPS/EMI/cash-deposit/internal transfers, shown separately in the Category Totals tab). All figures pull live via SUMIFS from each account's raw sheet.
A4: Date | B4: TNS Traders (HDFC 7278) GPay In | C4: TNS Traders (HDFC 7278) GPay Out | D4: Nagarajan (HDFC 6393) GPay In | E4: Nagarajan (HDFC 6393) GPay Out | F4: Nagarajan (ICICI 0314) GPay In | G4: Nagarajan (ICICI 0314) GPay Out | H4: Total GPay In (all accounts)
A5: 2026-07-06 | B5: =SUMIFS('TNS-HDFC 7278'!E:E,'TNS-HDFC 7278'!A:A,A5,'TNS-HDFC 7278'!C:C,"UPI") -> 0 | C5: =SUMIFS('TNS-HDFC 7278'!D:D,'TNS-HDFC 7278'!A:A,A5,'TNS-HDFC 7278'!C:C,"UPI") -> 0 | D5: =SUMIFS('Nagarajan-HDFC 6393'!E:E,'Nagarajan-HDFC 6393'!A:A,A5,'Nagarajan-HDFC 6393'!C:C,"UPI") -> 28310 | E5: =SUMIFS('Nagarajan-HDFC 6393'!D:D,'Nagarajan-HDFC 6393'!A:A,A5,'Nagarajan-HDFC 6393'!C:C,"UPI") -> 0 | F5: =SUMIFS('Nagarajan-ICICI 0314'!E:E,'Nagarajan-ICICI 0314'!A:A,A5,'Nagarajan-ICICI 0314'!C:C,"UPI") -> 0 | G5: =SUMIFS('Nagarajan-ICICI 0314'!D:D,'Nagarajan-ICICI 0314'!A:A,A5,'Nagarajan-ICICI 0314'!C:C,"UPI") -> 1316 | H5: =B5+D5+F5 -> 28310
A6: 2026-07-07 | B6: =SUMIFS('TNS-HDFC 7278'!E:E,'TNS-HDFC 7278'!A:A,A6,'TNS-HDFC 7278'!C:C,"UPI") -> 0 | C6: =SUMIFS('TNS-HDFC 7278'!D:D,'TNS-HDFC 7278'!A:A,A6,'TNS-HDFC 7278'!C:C,"UPI") -> 0 | D6: =SUMIFS('Nagarajan-HDFC 6393'!E:E,'Nagarajan-HDFC 6393'!A:A,A6,'Nagarajan-HDFC 6393'!C:C,"UPI") -> 28440 | E6: =SUMIFS('Nagarajan-HDFC 6393'!D:D,'Nagarajan-HDFC 6393'!A:A,A6,'Nagarajan-HDFC 6393'!C:C,"UPI") -> 0 | F6: =SUMIFS('Nagarajan-ICICI 0314'!E:E,'Nagarajan-ICICI 0314'!A:A,A6,'Nagarajan-ICICI 0314'!C:C,"UPI") -> 0 | G6: =SUMIFS('Nagarajan-ICICI 0314'!D:D,'Nagarajan-ICICI 0314'!A:A,A6,'Nagarajan-ICICI 0314'!C:C,"UPI") -> 12220 | H6: =B6+D6+F6 -> 28440
A7: 2026-07-08 | B7: =SUMIFS('TNS-HDFC 7278'!E:E,'TNS-HDFC 7278'!A:A,A7,'TNS-HDFC 7278'!C:C,"UPI") -> 0 | C7: =SUMIFS('TNS-HDFC 7278'!D:D,'TNS-HDFC 7278'!A:A,A7,'TNS-HDFC 7278'!C:C,"UPI") -> 0 | D7: =SUMIFS('Nagarajan-HDFC 6393'!E:E,'Nagarajan-HDFC 6393'!A:A,A7,'Nagarajan-HDFC 6393'!C:C,"UPI") -> 920 | E7: =SUMIFS('Nagarajan-HDFC 6393'!D:D,'Nagarajan-HDFC 6393'!A:A,A7,'Nagarajan-HDFC 6393'!C:C,"UPI") -> 0 | F7: =SUMIFS('Nagarajan-ICICI 0314'!E:E,'Nagarajan-ICICI 0314'!A:A,A7,'Nagarajan-ICICI 0314'!C:C,"UPI") -> 0 | G7: =SUMIFS('Nagarajan-ICICI 0314'!D:D,'Nagarajan-ICICI 0314'!A:A,A7,'Nagarajan-ICICI 0314'!C:C,"UPI") -> 250 | H7: =B7+D7+F7 -> 920
A8: 2026-07-09 | B8: =SUMIFS('TNS-HDFC 7278'!E:E,'TNS-HDFC 7278'!A:A,A8,'TNS-HDFC 7278'!C:C,"UPI") -> 0 | C8: =SUMIFS('TNS-HDFC 7278'!D:D,'TNS-HDFC 7278'!A:A,A8,'TNS-HDFC 7278'!C:C,"UPI") -> 0 | D8: =SUMIFS('Nagarajan-HDFC 6393'!E:E,'Nagarajan-HDFC 6393'!A:A,A8,'Nagarajan-HDFC 6393'!C:C,"UPI") -> 0 | E8: =SUMIFS('Nagarajan-HDFC 6393'!D:D,'Nagarajan-HDFC 6393'!A:A,A8,'Nagarajan-HDFC 6393'!C:C,"UPI") -> 0 | F8: =SUMIFS('Nagarajan-ICICI 0314'!E:E,'Nagarajan-ICICI 0314'!A:A,A8,'Nagarajan-ICICI 0314'!C:C,"UPI") -> 0 | G8: =SUMIFS('Nagarajan-ICICI 0314'!D:D,'Nagarajan-ICICI 0314'!A:A,A8,'Nagarajan-ICICI 0314'!C:C,"UPI") -> 10900 | H8: =B8+D8+F8 -> 0
A9: 2026-07-10 | B9: =SUMIFS('TNS-HDFC 7278'!E:E,'TNS-HDFC 7278'!A:A,A9,'TNS-HDFC 7278'!C:C,"UPI") -> 0 | C9: =SUMIFS('TNS-HDFC 7278'!D:D,'TNS-HDFC 7278'!A:A,A9,'TNS-HDFC 7278'!C:C,"UPI") -> 0 | D9: =SUMIFS('Nagarajan-HDFC 6393'!E:E,'Nagarajan-HDFC 6393'!A:A,A9,'Nagarajan-HDFC 6393'!C:C,"UPI") -> 0 | E9: =SUMIFS('Nagarajan-HDFC 6393'!D:D,'Nagarajan-HDFC 6393'!A:A,A9,'Nagarajan-HDFC 6393'!C:C,"UPI") -> 0 | F9: =SUMIFS('Nagarajan-ICICI 0314'!E:E,'Nagarajan-ICICI 0314'!A:A,A9,'Nagarajan-ICICI 0314'!C:C,"UPI") -> 0 | G9: =SUMIFS('Nagarajan-ICICI 0314'!D:D,'Nagarajan-ICICI 0314'!A:A,A9,'Nagarajan-ICICI 0314'!C:C,"UPI") -> 10630 | H9: =B9+D9+F9 -> 0
A10: 2026-07-11 | B10: =SUMIFS('TNS-HDFC 7278'!E:E,'TNS-HDFC 7278'!A:A,A10,'TNS-HDFC 7278'!C:C,"UPI") -> 0 | C10: =SUMIFS('TNS-HDFC 7278'!D:D,'TNS-HDFC 7278'!A:A,A10,'TNS-HDFC 7278'!C:C,"UPI") -> 0 | D10: =SUMIFS('Nagarajan-HDFC 6393'!E:E,'Nagarajan-HDFC 6393'!A:A,A10,'Nagarajan-HDFC 6393'!C:C,"UPI") -> 220 | E10: =SUMIFS('Nagarajan-HDFC 6393'!D:D,'Nagarajan-HDFC 6393'!A:A,A10,'Nagarajan-HDFC 6393'!C:C,"UPI") -> 1500 | F10: =SUMIFS('Nagarajan-ICICI 0314'!E:E,'Nagarajan-ICICI 0314'!A:A,A10,'Nagarajan-ICICI 0314'!C:C,"UPI") -> 0 | G10: =SUMIFS('Nagarajan-ICICI 0314'!D:D,'Nagarajan-ICICI 0314'!A:A,A10,'Nagarajan-ICICI 0314'!C:C,"UPI") -> 70 | H10: =B10+D10+F10 -> 220
A11: 2026-07-12 | B11: =SUMIFS('TNS-HDFC 7278'!E:E,'TNS-HDFC 7278'!A:A,A11,'TNS-HDFC 7278'!C:C,"UPI") -> 0 | C11: =SUMIFS('TNS-HDFC 7278'!D:D,'TNS-HDFC 7278'!A:A,A11,'TNS-HDFC 7278'!C:C,"UPI") -> 0 | D11: =SUMIFS('Nagarajan-HDFC 6393'!E:E,'Nagarajan-HDFC 6393'!A:A,A11,'Nagarajan-HDFC 6393'!C:C,"UPI") -> 0 | E11: =SUMIFS('Nagarajan-HDFC 6393'!D:D,'Nagarajan-HDFC 6393'!A:A,A11,'Nagarajan-HDFC 6393'!C:C,"UPI") -> 0 | F11: =SUMIFS('Nagarajan-ICICI 0314'!E:E,'Nagarajan-ICICI 0314'!A:A,A11,'Nagarajan-ICICI 0314'!C:C,"UPI") -> 0 | G11: =SUMIFS('Nagarajan-ICICI 0314'!D:D,'Nagarajan-ICICI 0314'!A:A,A11,'Nagarajan-ICICI 0314'!C:C,"UPI") -> 236 | H11: =B11+D11+F11 -> 0
A12: 2026-07-13 | B12: =SUMIFS('TNS-HDFC 7278'!E:E,'TNS-HDFC 7278'!A:A,A12,'TNS-HDFC 7278'!C:C,"UPI") -> 0 | C12: =SUMIFS('TNS-HDFC 7278'!D:D,'TNS-HDFC 7278'!A:A,A12,'TNS-HDFC 7278'!C:C,"UPI") -> 0 | D12: =SUMIFS('Nagarajan-HDFC 6393'!E:E,'Nagarajan-HDFC 6393'!A:A,A12,'Nagarajan-HDFC 6393'!C:C,"UPI") -> 32500 | E12: =SUMIFS('Nagarajan-HDFC 6393'!D:D,'Nagarajan-HDFC 6393'!A:A,A12,'Nagarajan-HDFC 6393'!C:C,"UPI") -> 32500 | F12: =SUMIFS('Nagarajan-ICICI 0314'!E:E,'Nagarajan-ICICI 0314'!A:A,A12,'Nagarajan-ICICI 0314'!C:C,"UPI") -> 0 | G12: =SUMIFS('Nagarajan-ICICI 0314'!D:D,'Nagarajan-ICICI 0314'!A:A,A12,'Nagarajan-ICICI 0314'!C:C,"UPI") -> 190 | H12: =B12+D12+F12 -> 32500
A13: 2026-07-14 | B13: =SUMIFS('TNS-HDFC 7278'!E:E,'TNS-HDFC 7278'!A:A,A13,'TNS-HDFC 7278'!C:C,"UPI") -> 0 | C13: =SUMIFS('TNS-HDFC 7278'!D:D,'TNS-HDFC 7278'!A:A,A13,'TNS-HDFC 7278'!C:C,"UPI") -> 0 | D13: =SUMIFS('Nagarajan-HDFC 6393'!E:E,'Nagarajan-HDFC 6393'!A:A,A13,'Nagarajan-HDFC 6393'!C:C,"UPI") -> 2000 | E13: =SUMIFS('Nagarajan-HDFC 6393'!D:D,'Nagarajan-HDFC 6393'!A:A,A13,'Nagarajan-HDFC 6393'!C:C,"UPI") -> 1952 | F13: =SUMIFS('Nagarajan-ICICI 0314'!E:E,'Nagarajan-ICICI 0314'!A:A,A13,'Nagarajan-ICICI 0314'!C:C,"UPI") -> 0 | G13: =SUMIFS('Nagarajan-ICICI 0314'!D:D,'Nagarajan-ICICI 0314'!A:A,A13,'Nagarajan-ICICI 0314'!C:C,"UPI") -> 3250 | H13: =B13+D13+F13 -> 2000
A14: 2026-07-15 | B14: =SUMIFS('TNS-HDFC 7278'!E:E,'TNS-HDFC 7278'!A:A,A14,'TNS-HDFC 7278'!C:C,"UPI") -> 0 | C14: =SUMIFS('TNS-HDFC 7278'!D:D,'TNS-HDFC 7278'!A:A,A14,'TNS-HDFC 7278'!C:C,"UPI") -> 0 | D14: =SUMIFS('Nagarajan-HDFC 6393'!E:E,'Nagarajan-HDFC 6393'!A:A,A14,'Nagarajan-HDFC 6393'!C:C,"UPI") -> 0 | E14: =SUMIFS('Nagarajan-HDFC 6393'!D:D,'Nagarajan-HDFC 6393'!A:A,A14,'Nagarajan-HDFC 6393'!C:C,"UPI") -> 5180 | F14: =SUMIFS('Nagarajan-ICICI 0314'!E:E,'Nagarajan-ICICI 0314'!A:A,A14,'Nagarajan-ICICI 0314'!C:C,"UPI") -> 0 | G14: =SUMIFS('Nagarajan-ICICI 0314'!D:D,'Nagarajan-ICICI 0314'!A:A,A14,'Nagarajan-ICICI 0314'!C:C,"UPI") -> 0 | H14: =B14+D14+F14 -> 0
A15: 2026-07-16 | B15: =SUMIFS('TNS-HDFC 7278'!E:E,'TNS-HDFC 7278'!A:A,A15,'TNS-HDFC 7278'!C:C,"UPI") -> 0 | C15: =SUMIFS('TNS-HDFC 7278'!D:D,'TNS-HDFC 7278'!A:A,A15,'TNS-HDFC 7278'!C:C,"UPI") -> 0 | D15: =SUMIFS('Nagarajan-HDFC 6393'!E:E,'Nagarajan-HDFC 6393'!A:A,A15,'Nagarajan-HDFC 6393'!C:C,"UPI") -> 0 | E15: =SUMIFS('Nagarajan-HDFC 6393'!D:D,'Nagarajan-HDFC 6393'!A:A,A15,'Nagarajan-HDFC 6393'!C:C,"UPI") -> 4825 | F15: =SUMIFS('Nagarajan-ICICI 0314'!E:E,'Nagarajan-ICICI 0314'!A:A,A15,'Nagarajan-ICICI 0314'!C:C,"UPI") -> 0 | G15: =SUMIFS('Nagarajan-ICICI 0314'!D:D,'Nagarajan-ICICI 0314'!A:A,A15,'Nagarajan-ICICI 0314'!C:C,"UPI") -> 0 | H15: =B15+D15+F15 -> 0
A16: 2026-07-17 | B16: =SUMIFS('TNS-HDFC 7278'!E:E,'TNS-HDFC 7278'!A:A,A16,'TNS-HDFC 7278'!C:C,"UPI") -> 0 | C16: =SUMIFS('TNS-HDFC 7278'!D:D,'TNS-HDFC 7278'!A:A,A16,'TNS-HDFC 7278'!C:C,"UPI") -> 0 | D16: =SUMIFS('Nagarajan-HDFC 6393'!E:E,'Nagarajan-HDFC 6393'!A:A,A16,'Nagarajan-HDFC 6393'!C:C,"UPI") -> 1750 | E16: =SUMIFS('Nagarajan-HDFC 6393'!D:D,'Nagarajan-HDFC 6393'!A:A,A16,'Nagarajan-HDFC 6393'!C:C,"UPI") -> 1200 | F16: =SUMIFS('Nagarajan-ICICI 0314'!E:E,'Nagarajan-ICICI 0314'!A:A,A16,'Nagarajan-ICICI 0314'!C:C,"UPI") -> 0 | G16: =SUMIFS('Nagarajan-ICICI 0314'!D:D,'Nagarajan-ICICI 0314'!A:A,A16,'Nagarajan-ICICI 0314'!C:C,"UPI") -> 0 | H16: =B16+D16+F16 -> 1750
... A62: 2026-09-01 | B62: =SUMIFS('TNS-HDFC 7278'!E:E,'TNS-HDFC 7278'!A:A,A62,'TNS-HDFC 7278'!C:C,"UPI") -> 0 | C62: =SUMIFS('TNS-HDFC 7278'!D:D,'TNS-HDFC 7278'!A:A,A62,'TNS-HDFC 7278'!C:C,"UPI") -> 0 | D62: =SUMIFS('Nagarajan-HDFC 6393'!E:E,'Nagarajan-HDFC 6393'!A:A,A62,'Nagarajan-HDFC 6393'!C:C,"UPI") -> 0 | E62: =SUMIFS('Nagarajan-HDFC 6393'!D:D,'Nagarajan-HDFC 6393'!A:A,A62,'Nagarajan-HDFC 6393'!C:C,"UPI") -> 135 | F62: =SUMIFS('Nagarajan-ICICI 0314'!E:E,'Nagarajan-ICICI 0314'!A:A,A62,'Nagarajan-ICICI 0314'!C:C,"UPI") -> 0 | G62: =SUMIFS('Nagarajan-ICICI 0314'!D:D,'Nagarajan-ICICI 0314'!A:A,A62,'Nagarajan-ICICI 0314'!C:C,"UPI") -> 0 | H62: =B62+D62+F62 -> 0
A63: TOTAL | B63: =SUM(B5:B62) -> 124820 | C63: =SUM(C5:C62) -> 37989.8 | D63: =SUM(D5:D62) -> 144708 | E63: =SUM(E5:E62) -> 261889 | F63: =SUM(F5:F62) -> 1 | G63: =SUM(G5:G62) -> 310470.9 | H63: =SUM(H5:H62) -> 269529

Sheet Category Totals
A1: Transaction Category Totals by Account
A2: Every rupee in each statement, split by transaction type — confirms nothing was missed classifying UPI vs NEFT/IMPS/EMI/etc.
A4: TNS Traders (HDFC 7278)
A5: Category | B5: Withdrawal (₹) | C5: Deposit (₹) | D5: Count
A6: UPI | B6: =SUMIFS('TNS-HDFC 7278'!D:D,'TNS-HDFC 7278'!C:C,A6) -> 37989.8 | C6: =SUMIFS('TNS-HDFC 7278'!E:E,'TNS-HDFC 7278'!C:C,A6) -> 124820 | D6: =COUNTIF('TNS-HDFC 7278'!C:C,A6) -> 224
A7: NEFT | B7: =SUMIFS('TNS-HDFC 7278'!D:D,'TNS-HDFC 7278'!C:C,A7) -> 0 | C7: =SUMIFS('TNS-HDFC 7278'!E:E,'TNS-HDFC 7278'!C:C,A7) -> 0 | D7: =COUNTIF('TNS-HDFC 7278'!C:C,A7) -> 0
A8: IMPS | B8: =SUMIFS('TNS-HDFC 7278'!D:D,'TNS-HDFC 7278'!C:C,A8) -> 0 | C8: =SUMIFS('TNS-HDFC 7278'!E:E,'TNS-HDFC 7278'!C:C,A8) -> 0 | D8: =COUNTIF('TNS-HDFC 7278'!C:C,A8) -> 0
A9: EMI | B9: =SUMIFS('TNS-HDFC 7278'!D:D,'TNS-HDFC 7278'!C:C,A9) -> 0 | C9: =SUMIFS('TNS-HDFC 7278'!E:E,'TNS-HDFC 7278'!C:C,A9) -> 0 | D9: =COUNTIF('TNS-HDFC 7278'!C:C,A9) -> 0
A10: FT (internal transfer) | B10: =SUMIFS('TNS-HDFC 7278'!D:D,'TNS-HDFC 7278'!C:C,A10) -> 0 | C10: =SUMIFS('TNS-HDFC 7278'!E:E,'TNS-HDFC 7278'!C:C,A10) -> 50000 | D10: =COUNTIF('TNS-HDFC 7278'!C:C,A10) -> 1
A11: Cash Deposit | B11: =SUMIFS('TNS-HDFC 7278'!D:D,'TNS-HDFC 7278'!C:C,A11) -> 0 | C11: =SUMIFS('TNS-HDFC 7278'!E:E,'TNS-HDFC 7278'!C:C,A11) -> 0 | D11: =COUNTIF('TNS-HDFC 7278'!C:C,A11) -> 0
A12: Bill/Internet transfer | B12: =SUMIFS('TNS-HDFC 7278'!D:D,'TNS-HDFC 7278'!C:C,A12) -> 0 | C12: =SUMIFS('TNS-HDFC 7278'!E:E,'TNS-HDFC 7278'!C:C,A12) -> 0 | D12: =COUNTIF('TNS-HDFC 7278'!C:C,A12) -> 0
A13: Other | B13: =SUMIFS('TNS-HDFC 7278'!D:D,'TNS-HDFC 7278'!C:C,A13) -> 21.04 | C13: =SUMIFS('TNS-HDFC 7278'!E:E,'TNS-HDFC 7278'!C:C,A13) -> 0 | D13: =COUNTIF('TNS-HDFC 7278'!C:C,A13) -> 5
A14: Account Total | B14: =SUM(B6:B13) -> 38010.84 | C14: =SUM(C6:C13) -> 174820
A16: Nagarajan (HDFC 6393)
A17: Category | B17: Withdrawal (₹) | C17: Deposit (₹) | D17: Count
A18: UPI | B18: =SUMIFS('Nagarajan-HDFC 6393'!D:D,'Nagarajan-HDFC 6393'!C:C,A18) -> 261889 | C18: =SUMIFS('Nagarajan-HDFC 6393'!E:E,'Nagarajan-HDFC 6393'!C:C,A18) -> 144708 | D18: =COUNTIF('Nagarajan-HDFC 6393'!C:C,A18) -> 163
A19: NEFT | B19: =SUMIFS('Nagarajan-HDFC 6393'!D:D,'Nagarajan-HDFC 6393'!C:C,A19) -> 0 | C19: =SUMIFS('Nagarajan-HDFC 6393'!E:E,'Nagarajan-HDFC 6393'!C:C,A19) -> 80000 | D19: =COUNTIF('Nagarajan-HDFC 6393'!C:C,A19) -> 1
A20: IMPS | B20: =SUMIFS('Nagarajan-HDFC 6393'!D:D,'Nagarajan-HDFC 6393'!C:C,A20) -> 0 | C20: =SUMIFS('Nagarajan-HDFC 6393'!E:E,'Nagarajan-HDFC 6393'!C:C,A20) -> 60001 | D20: =COUNTIF('Nagarajan-HDFC 6393'!C:C,A20) -> 4
A21: EMI | B21: =SUMIFS('Nagarajan-HDFC 6393'!D:D,'Nagarajan-HDFC 6393'!C:C,A21) -> 39957 | C21: =SUMIFS('Nagarajan-HDFC 6393'!E:E,'Nagarajan-HDFC 6393'!C:C,A21) -> 13319 | D21: =COUNTIF('Nagarajan-HDFC 6393'!C:C,A21) -> 4
A22: FT (internal transfer) | B22: =SUMIFS('Nagarajan-HDFC 6393'!D:D,'Nagarajan-HDFC 6393'!C:C,A22) -> 50000 | C22: =SUMIFS('Nagarajan-HDFC 6393'!E:E,'Nagarajan-HDFC 6393'!C:C,A22) -> 0 | D22: =COUNTIF('Nagarajan-HDFC 6393'!C:C,A22) -> 1
A23: Cash Deposit | B23: =SUMIFS('Nagarajan-HDFC 6393'!D:D,'Nagarajan-HDFC 6393'!C:C,A23) -> 0 | C23: =SUMIFS('Nagarajan-HDFC 6393'!E:E,'Nagarajan-HDFC 6393'!C:C,A23) -> 0 | D23: =COUNTIF('Nagarajan-HDFC 6393'!C:C,A23) -> 0
A24: Bill/Internet transfer | B24: =SUMIFS('Nagarajan-HDFC 6393'!D:D,'Nagarajan-HDFC 6393'!C:C,A24) -> 0 | C24: =SUMIFS('Nagarajan-HDFC 6393'!E:E,'Nagarajan-HDFC 6393'!C:C,A24) -> 0 | D24: =COUNTIF('Nagarajan-HDFC 6393'!C:C,A24) -> 0
A25: Other | B25: =SUMIFS('Nagarajan-HDFC 6393'!D:D,'Nagarajan-HDFC 6393'!C:C,A25) -> 450 | C25: =SUMIFS('Nagarajan-HDFC 6393'!E:E,'Nagarajan-HDFC 6393'!C:C,A25) -> 36.45 | D25: =COUNTIF('Nagarajan-HDFC 6393'!C:C,A25) -> 2
A26: Account Total | B26: =SUM(B18:B25) -> 352296 | C26: =SUM(C18:C25) -> 298064.45
A28: Nagarajan (ICICI 0314)
A29: Category | B29: Withdrawal (₹) | C29: Deposit (₹) | D29: Count
A30: UPI | B30: =SUMIFS('Nagarajan-ICICI 0314'!D:D,'Nagarajan-ICICI 0314'!C:C,A30) -> 310470.9 | C30: =SUMIFS('Nagarajan-ICICI 0314'!E:E,'Nagarajan-ICICI 0314'!C:C,A30) -> 1 | D30: =COUNTIF('Nagarajan-ICICI 0314'!C:C,A30) -> 111
A31: NEFT | B31: =SUMIFS('Nagarajan-ICICI 0314'!D:D,'Nagarajan-ICICI 0314'!C:C,A31) -> 0 | C31: =SUMIFS('Nagarajan-ICICI 0314'!E:E,'Nagarajan-ICICI 0314'!C:C,A31) -> 263460 | D31: =COUNTIF('Nagarajan-ICICI 0314'!C:C,A31) -> 46
A32: IMPS | B32: =SUMIFS('Nagarajan-ICICI 0314'!D:D,'Nagarajan-ICICI 0314'!C:C,A32) -> 60001 | C32: =SUMIFS('Nagarajan-ICICI 0314'!E:E,'Nagarajan-ICICI 0314'!C:C,A32) -> 0 | D32: =COUNTIF('Nagarajan-ICICI 0314'!C:C,A32) -> 4
A33: EMI | B33: =SUMIFS('Nagarajan-ICICI 0314'!D:D,'Nagarajan-ICICI 0314'!C:C,A33) -> 0 | C33: =SUMIFS('Nagarajan-ICICI 0314'!E:E,'Nagarajan-ICICI 0314'!C:C,A33) -> 0 | D33: =COUNTIF('Nagarajan-ICICI 0314'!C:C,A33) -> 0
A34: FT (internal transfer) | B34: =SUMIFS('Nagarajan-ICICI 0314'!D:D,'Nagarajan-ICICI 0314'!C:C,A34) -> 0 | C34: =SUMIFS('Nagarajan-ICICI 0314'!E:E,'Nagarajan-ICICI 0314'!C:C,A34) -> 0 | D34: =COUNTIF('Nagarajan-ICICI 0314'!C:C,A34) -> 0
A35: Cash Deposit | B35: =SUMIFS('Nagarajan-ICICI 0314'!D:D,'Nagarajan-ICICI 0314'!C:C,A35) -> 0 | C35: =SUMIFS('Nagarajan-ICICI 0314'!E:E,'Nagarajan-ICICI 0314'!C:C,A35) -> 97000 | D35: =COUNTIF('Nagarajan-ICICI 0314'!C:C,A35) -> 3
A36: Bill/Internet transfer | B36: =SUMIFS('Nagarajan-ICICI 0314'!D:D,'Nagarajan-ICICI 0314'!C:C,A36) -> 80000 | C36: =SUMIFS('Nagarajan-ICICI 0314'!E:E,'Nagarajan-ICICI 0314'!C:C,A36) -> 0 | D36: =COUNTIF('Nagarajan-ICICI 0314'!C:C,A36) -> 1
A37: Other | B37: =SUMIFS('Nagarajan-ICICI 0314'!D:D,'Nagarajan-ICICI 0314'!C:C,A37) -> 0 | C37: =SUMIFS('Nagarajan-ICICI 0314'!E:E,'Nagarajan-ICICI 0314'!C:C,A37) -> 0 | D37: =COUNTIF('Nagarajan-ICICI 0314'!C:C,A37) -> 0
A38: Account Total | B38: =SUM(B30:B37) -> 450471.9 | C38: =SUM(C30:C37) -> 360461

Sheet Cash Reconciliation Notes
A1: Cash-in-Hand Discrepancy — Diagnostic Notes
A3: 1. What was verified with certainty
A5: All three bank statements were parsed programmatically (not by eye) from the PDF text layer. Every account's extracted Withdrawal and Deposit totals were checked against that statement's own printed summary line and match to the paisa:
A7: • TNS Traders (HDFC 7278): Debits ₹38,010.84 / Credits ₹1,74,820.00 — matches statement summary exactly.
A9: • Nagarajan (HDFC 6393): Debits ₹3,52,296.00 / Credits ₹2,98,064.45 — matches statement summary exactly.
A11: • Nagarajan (ICICI 0314): opening balance + deposits − withdrawals reproduces the statement's final closing balance (₹10.13) to the paisa.
A13: The "GPay-UPI Summary" and "Category Totals" tabs are the direct, fully-verified answer to "overall GPay expense amount & incoming amount, account-wise and date-wise."
A15: 2. The cash-in-hand number could not be reconciled from this session's data — here is exactly why
A17: The Poondu Ledger app's "Cash In Hand" dashboard tile is bound to a formula the app itself labels "Cash In Hand (LIQUID)" — its own on-screen note says it "Combines Cash + GPay." I pulled the live ledger data directly from the deployed app (same source it reads from) and recomputed that exact formula in Python line-for-line. Result: ₹8,31,396 — not the ₹12,18,047 you quoted. That is a ₹3,86,651 gap I cannot explain from data available in this session.
A19: This means the ₹12,18,047 figure either came from a browser tab that had not refreshed against the sheet since some recent entries/deletions were made, or from a different tile/moment than the one I recomputed. Before chasing the "true" gap any further, please hard-refresh the Poondu Ledger app and re-read the Cash In Hand tile — if it still reads ₹12,18,047 against a freshly-loaded page, tell me and I will re-derive the formula from the live page's own JS execution rather than from a static copy of index.html, in case the deployed code has drifted from the file I have on record.
A21: 3. The real architectural finding — true regardless of which of the two numbers above is right
A23: Every sale and expense in the ledger from July 2 through September 1 is flagged isCash:true, with exactly ONE exception (one ₹11,000 credit sale). That is not a coincidence — the Cash / GPay / Credit payment-mode split was only added to the app THIS session (Sept 2). Every entry made before today defaulted to isCash:true because that field did not meaningfully exist yet.
... A39: (c) I can build a one-time "bulk re-tag" screen in the app (list all isCash:true sales in a date range, let you flip individual ones to GPay in bulk) if manually editing each one in Google Sheets is too slow — say the word and I'll scope it.

Sheet Nagarajan Spend Aug1-31
A1: Nagarajan Personal Accounts - Spend Detail, Aug 1-16 vs Aug 17-31
A2: Covers both HDFC 6393 and ICICI 0314. "Spend" = Withdrawal column. Col H flags internal money movement (self-transfer between the two personal accounts, or capital sent to TNS Traders current a/c) - not real spend. Col I flags verified genuine shop/procurement purchases (AKJ Traders, Dhanalakshmi Poondu garlic supplier) - matched only where the supplier name is the FIRST word of the narration, to avoid a known trailing-text parsing artifact on ICICI rows.
A4: SUMMARY
A5: Window | B5: Total Spend | C5: Spend txns | D5: Internal transfers (excl.) | E5: Genuine shop/procurement spend | F5: Other/personal spend (remainder)
A6: W1: Aug 1-16 | B6: =SUMIF(A11:A179,A6,F11:F179) -> 203761 | C6: =COUNTIFS(A11:A179,A6,F11:F179,">0") -> 76 | D6: =SUMIFS(F11:F179,A11:A179,A6,H11:H179,"<>") -> 110000 | E6: =SUMIFS(F11:F179,A11:A179,A6,I11:I179,"<>") -> 19100 | F6: =B6-D6-E6 -> 74661
A7: W2: Aug 17-31 | B7: =SUMIF(A11:A179,A7,F11:F179) -> 54884.9 | C7: =COUNTIFS(A11:A179,A7,F11:F179,">0") -> 39 | D7: =SUMIFS(F11:F179,A11:A179,A7,H11:H179,"<>") -> 0 | E7: =SUMIFS(F11:F179,A11:A179,A7,I11:I179,"<>") -> 49315 | F7: =B7-D7-E7 -> 5569.9
A9: DETAIL (all transactions, both accounts)
A10: Window | B10: Date | C10: Account | D10: Category | E10: Narration | F10: Withdrawal (Spend) | G10: Deposit | H10: Internal / Not a real spend? | I10: Genuine shop purchase?
A11: W1: Aug 1-16 | B11: 2026-08-01 | C11: HDFC 6393 | D11: UPI | E11: UPI-AKJ TRADERS-NASSARAKJ786@OKAXIS-UTIB 0000477-127180727435-UPI | F11: 3600 | G11: 0 | I11: Yes - AKJ Traders (supplier)
A12: W1: Aug 1-16 | B12: 2026-08-01 | C12: HDFC 6393 | D12: UPI | E12: UPI-BADMAVATHI P-KAVIBHAVANA381@OKHDFCBA NK-CNRB0000033-127202893401-UPI | F12: 0 | G12: 320
A13: W1: Aug 1-16 | B13: 2026-08-01 | C13: HDFC 6393 | D13: UPI | E13: UPI-HARIRITHANYA M-MUTHUKUMARP14771-5@O KAXIS-UCBA0000030-621306091961-UPI | F13: 0 | G13: 1000
A14: W1: Aug 1-16 | B14: 2026-08-01 | C14: ICICI 0314 | D14: NEFT | E14: PhonePe Limited NEFT-YESAP62134270843-PhonePe Limited-F09 M22UYYZ10YB2URED-002261100000025- YESB0000001 PhonePe Limited | F14: 0 | G14: 2165
A15: W1: Aug 1-16 | B15: 2026-08-02 | C15: HDFC 6393 | D15: UPI | E15: UPI-FORSRE MUTHUKUMARAN-PAYTM-8802906@P TYS-YESB0PTMUPI-127253749648-UPI | F15: 200 | G15: 0
A16: W1: Aug 1-16 | B16: 2026-08-02 | C16: HDFC 6393 | D16: UPI | E16: UPI-MRSBASKAR-BASKAR3739@OKICICI-IDIB0 00T015-621476312407-TRANSPORT | F16: 5200 | G16: 0
A17: W1: Aug 1-16 | B17: 2026-08-02 | C17: ICICI 0314 | D17: NEFT | E17: PhonePe Limited NEFT-YESAP62144194966-PhonePe Limited-F09 M22UYYZ10YB2URED-002261100000025- YESB0000001 PhonePe Limited | F17: 0 | G17: 14295
A18: W1: Aug 1-16 | B18: 2026-08-03 | C18: HDFC 6393 | D18: UPI | E18: UPI-J UDAYAKUMAR-UDAYSON007@OKAXIS-UTIB0 001294-621586033782-UPI | F18: 0 | G18: 250
A19: W1: Aug 1-16 | B19: 2026-08-03 | C19: HDFC 6393 | D19: UPI | E19: UPI-SAVALARAM-PAYTMQR6MYBWG@PTYS-YESB0PT MUPI-127300151139-UPI HDFCBANKLIMITED *Closingbalanceincludesfundsearmarkedforholdandunclearedfunds Contentsofthisstatementwillbeconsideredcorrectifnoerrorisreportedwithin30daysofreceiptofstatement.TheaddressonthisstatementisthatonrecordwiththeBankasatthedayofrequesting thisstatement. StateaccountbranchGSTN:33AAACH2702H1Z7 HDFCBankGSTINnumberdetailsareavailableathttps://www.hdfcbank.com/personal/making-payments/online-tax-payment/goods-and-service-tax. RegisteredOfficeAddress:HDFCBankHouse,SenapatiBapatMarg,LowerParel,Mumbai400013 | F19: 400 | G19: 0
A20: W1: Aug 1-16 | B20: 2026-08-03 | C20: HDFC 6393 | D20: UPI | E20: UPI-MRMANIMARAN MUTHUSA-BHARATPE.9Q0U0B 0Y8Q580770@UNITYPE-SBIN0000990-127300844 945-PAYTOBHARATPEME | F20: 30 | G20: 0
A21: W1: Aug 1-16 | B21: 2026-08-03 | C21: HDFC 6393 | D21: UPI | E21: UPI-SHAJAHAN IBRAHIM-9043533162@YBL-TMBL 0000059-030446898923-PAYMENTFROMPHONE | F21: 0 | G21: 1000
A22: W1: Aug 1-16 | B22: 2026-08-03 | C22: HDFC 6393 | D22: IMPS | E22: IMPS-621514265120-NAGARAJANT-ICIC-XXXXX XXX0314-IMPSTRANSACTION | F22: 0 | G22: 40000 | H22: Yes - self-transfer between own 2 accounts
A23: W1: Aug 1-16 | B23: 2026-08-03 | C23: HDFC 6393 | D23: UPI | E23: UPI-KALIAMMAL K-KALIYAMMALKALIYAMMAL510@ OKICICI-BKID0008201-658117462648-UPI | F23: 0 | G23: 1500
A24: W1: Aug 1-16 | B24: 2026-08-03 | C24: ICICI 0314 | D24: NEFT | E24: PhonePe Limited NEFT-YESAP62155029499-PhonePe Limited-F09 M22UYYZ10YB2URED-002261100000025- YESB0000001 NAGARAJAN | F24: 0 | G24: 8110
A25: W1: Aug 1-16 | B25: 2026-08-03 | C25: ICICI 0314 | D25: IMPS | E25: NAGARAJAN MMT/IMPS/621514265120/NAGARAJAN /HDFC0002231 PhonePe Limited | F25: 40000 | G25: 0 | H25: Yes - self-transfer between own 2 accounts
A26: W1: Aug 1-16 | B26: 2026-08-04 | C26: HDFC 6393 | D26: UPI | E26: UPI-CPMARUTHACHALAM AN-PAYTMQR6LT9FC@P TYS-YESB0PTMUPI-127343134719-UPI | F26: 200 | G26: 0
A27: W1: Aug 1-16 | B27: 2026-08-04 | C27: HDFC 6393 | D27: UPI | E27: UPI-NASSARAKJ786OKAXIS-NASSARAKJ786@OKAX IS-UTIB0000477-658218532149-UPI | F27: 8600 | G27: 0
A28: W1: Aug 1-16 | B28: 2026-08-04 | C28: HDFC 6393 | D28: UPI | E28: UPI-JSYED RABIYAMMAL-SHAFIYASHAFIYA686@ OKSBI-TNSC0011700-658278475714-UPI | F28: 3000 | G28: 0
A29: W1: Aug 1-16 | B29: 2026-08-04 | C29: HDFC 6393 | D29: UPI | E29: UPI-CPMARUTHACHALAM AN-PAYTMQR6LT9ES@P TYS-YESB0PTMUPI-127384649320-UPI | F29: 200 | G29: 0
A30: W1: Aug 1-16 | B30: 2026-08-04 | C30: ICICI 0314 | D30: NEFT | E30: PhonePe Limited NEFT-YESAP62164484795-PhonePe Limited-F09 M22UYYZ10YB2URED-002261100000025- YESB0000001 PhonePe Limited | F30: 0 | G30: 2635
A31: W1: Aug 1-16 | B31: 2026-08-05 | C31: HDFC 6393 | D31: UPI | E31: UPI-SURESHLESSISHOP3-Q844887125@YBL-Y ESB0YBLUPI-127412677917-UPI | F31: 50 | G31: 0
A32: W1: Aug 1-16 | B32: 2026-08-05 | C32: HDFC 6393 | D32: UPI | E32: UPI-KRISHS NAIR-KRISHSNAIR1@OKHDFCBANK- FDRL0001288-127438812736-GST | F32: 500 | G32: 0
A33: W1: Aug 1-16 | B33: 2026-08-05 | C33: HDFC 6393 | D33: UPI | E33: UPI-SARAVANANS M-SMSARAVANANSMSARAVANAN 2@OKICICI-CNRB0000033-658341668011-UPI | F33: 0 | G33: 130
A34: W1: Aug 1-16 | B34: 2026-08-05 | C34: ICICI 0314 | D34: NEFT | E34: PhonePe Limited NEFT-YESAP62174096931-PhonePe Limited-F09 M22UYYZ10YB2URED-002261100000025- YESB0000001 PhonePe Limited | F34: 0 | G34: 1700
A35: W1: Aug 1-16 | B35: 2026-08-06 | C35: HDFC 6393 | D35: UPI | E35: UPI-POPULARBAKESAND HDFCBANKLIMITED *Closingbalanceincludesfundsearmarkedforholdandunclearedfunds Contentsofthisstatementwillbeconsideredcorrectifnoerrorisreportedwithin30daysofreceiptofstatement.TheaddressonthisstatementisthatonrecordwiththeBankasatthedayofrequesting thisstatement. StateaccountbranchGSTN:33AAACH2702H1Z7 HDFCBankGSTINnumberdetailsareavailableathttps://www.hdfcbank.com/personal/making-payments/online-tax-payment/goods-and-service-tax. RegisteredOfficeAddress:HDFCBankHouse,SenapatiBapatMarg,LowerParel,Mumbai400013 | F35: 20 | G35: 0
A36: W1: Aug 1-16 | B36: 2026-08-06 | C36: HDFC 6393 | D36: IMPS | E36: IMPS-621811855692-NAGARAJANT-ICIC-XXXXX XXX0314-IMPSTRANSACTION | F36: 0 | G36: 10000 | H36: Yes - self-transfer between own 2 accounts
A37: W1: Aug 1-16 | B37: 2026-08-06 | C37: HDFC 6393 | D37: UPI | E37: UPI-NASSARAKJ786OKAXIS-NASSARAKJ786@OKAX IS-UTIB0000477-658492352651-UPI | F37: 3600 | G37: 0
A38: W1: Aug 1-16 | B38: 2026-08-06 | C38: HDFC 6393 | D38: FT (internal transfer) | E38: FT-DR-50200120147278-TNSTRADERS | F38: 50000 | G38: 0 | H38: Yes - to TNS Traders (capital, not spend)
A39: W1: Aug 1-16 | B39: 2026-08-06 | C39: HDFC 6393 | D39: UPI | E39: UPI-DHILSATH M-PAYTM.S281AHM@PTY-YESB0MC HUPI-127494779858-UPI | F39: 30 | G39: 0
A40: W1: Aug 1-16 | B40: 2026-08-06 | C40: ICICI 0314 | D40: NEFT | E40: PhonePe Limited NEFT-YESAP62184577325-PhonePe Limited-F09 M22UYYZ10YB2URED-002261100000025- YESB0000001 NAGARAJAN | F40: 0 | G40: 3802
A41: W1: Aug 1-16 | B41: 2026-08-06 | C41: ICICI 0314 | D41: IMPS | E41: NAGARAJAN MMT/IMPS/621811855692/NAGARAJAN /HDFC0002231 PhonePe Limited | F41: 10000 | G41: 0 | H41: Yes - self-transfer between own 2 accounts
A42: W1: Aug 1-16 | B42: 2026-08-07 | C42: HDFC 6393 | D42: UPI | E42: UPI-CPMARUTHACHALAM AN-PAYTMQR6LT9F6@P TYS-YESB0PTMUPI-127504623150-UPI | F42: 100 | G42: 0
...

Sheet TNS-HDFC 7278
A1: TNS Traders (HDFC 7278) — All Transactions
A2: Extracted programmatically from the bank-provided PDF statement. Verified: sum of Withdrawal/Deposit columns matches the statement's own summary totals exactly.
A4: Date | B4: Narration | C4: Category | D4: Withdrawal (₹) | E4: Deposit (₹) | F4: Balance (₹)
A5: 2026-08-06 | B5: FT-CR-50100072796393-NAGARAJANT | C5: FT (internal transfer) | E5: 50000 | F5: 50000
A6: 2026-08-11 | B6: UPISETTLEMENT-KES170-11/08/26 | C6: UPI | E6: 221 | F6: 50221
A7: 2026-08-15 | B7: UPISETTLEMENT-KES170-15/08/26 | C7: UPI | E7: 2600 | F7: 52821
A8: 2026-08-16 | B8: UPISETTLEMENT-KES170-16/08/26 | C8: UPI | E8: 360 | F8: 53181
A9: 2026-08-17 | B9: UPISETTLEMENT-KES170-17/08/26 | C9: UPI | E9: 3080 | F9: 56261
A10: 2026-08-18 | B10: UPISETTLEMENT-KES170-18/08/26 | C10: UPI | E10: 60 | F10: 56321
A11: 2026-08-19 | B11: UPISETTLEMENT-KES170-19/08/26 | C11: UPI | E11: 1095 | F11: 57416
A12: 2026-08-22 | B12: UPI-6897690963-DIVINESTARK111-2@OKICICI- 623436673528-UPI | C12: UPI | E12: 160 | F12: 57576
A13: 2026-08-22 | B13: UPI-916010046088863-SUREGARAJENDREN19@OK AXIS-623482505878-GARLIC | C13: UPI | E13: 235 | F13: 57811
A14: 2026-08-22 | B14: UPI-420150050800546-JAYATHANAM381@OKHDFC BANK-128302479729-UPI | C14: UPI | E14: 6300 | F14: 64111
A15: 2026-08-22 | B15: UPI-201021214733-9444203807@SUPERYES-623 420165407-PAIDVIASUPERMONEYUPI | C15: UPI | E15: 1160 | F15: 65271
A16: 2026-08-22 | B16: UPI-571910110004008-R.SHANMUKARAJA456-1@ OKHDFCBANK-128302805488-UPI | C16: UPI | E16: 290 | F16: 65561
... A58: 2026-08-24 | B58: UPI-170001000006229-NEELAVENI2204S@OKICI CI-623695066633-UPI | C58: UPI | E58: 500 | F58: 77191
A59: 2026-08-24 | B59: UPI-MRSHEMALATHA G-HEMAJANANIMSC-1@OKIC ICI-IDIB000R023-623659530405-UPI | C59: UPI | D59: 1 | F59: 77190
A60: 2026-08-24 | B60: UPI-AROMABAKERY NRS-Q318439692@YBL-YES B0YBLUPI-623650876912-UPISENDMONEY | C60: UPI | D60: 40 | F60: 77150
A61: 2026-08-24 | B61: UPI-115237828006-SAGEEB4U@OKHDFCBANK-128 426350581-UPI | C61: UPI | E61: 100 | F61: 77250
A62: 2026-08-24 | B62: UPI-VINOTHA KANNAIYAN-PAYTM.S2SMF3E@PTY- YESB0MCHUPI-128427188737-UPI | C62: UPI | D62: 50 | F62: 77200
A63: 2026-08-24 | B63: UPI-BOOMIRAJ T-BOOMI10MSP@OKICICI-SBIN0 016317-623600134363-UPI | C63: UPI | D63: 140 | F63: 77060
A64: 2026-08-24 | B64: UPI-053401000035032-7540042931@YBL-95610 9853560-PAYMENTFROMPHONEPE | C64: UPI | E64: 110 | F64: 77170
A65: 2026-08-24 | B65: UPI-1232101071071-SELLAPPANPALANISWAMI19 51@OKICICI-623669564220-UPI | C65: UPI | E65: 120 | F65: 77290
A66: 2026-08-24 | B66: UPI-00000067230099420-AMANULLA7217@OKSBI -623647241010-UPI | C66: UPI | E66: 180 | F66: 77470
A67: 2026-08-24 | B67: UPI-865987263-MAILME.RUBYV-3@OKICICI-623 672877153-UPI | C67: UPI | E67: 170 | F67: 77640
A68: 2026-08-24 | B68: UPI-65301800000021147648-9361823460@PTYE S-214002238410-SENTUSINGPAYTMUPI HDFCBANKLIMITED *Closingbalanceincludesfundsearmarkedforholdandunclearedfunds Contentsofthisstatementwillb | C68: UPI | E68: 90 | F68: 77730
A69: 2026-08-24 | B69: UPI-00000039069626292-BALAKRISHNANKISHOR E1984-1@OKICICI-623659894785-UPI | C69: UPI | E69: 80 | F69: 77810
A70: 2026-08-24 | B70: UPI-61542250010328-BRINDHAPAVAL85@OKAXIS -623618858820-UPI | C70: UPI | E70: 220 | F70: 78030
A71: 2026-08-24 | B71: UPI-820610110017417-SURENDRANSHANMUGAM2@ OKAXIS-623642680516-UPI | C71: UPI | E71: 500 | F71: 78530
A72: 2026-08-24 | B72: UPI-6818980282-GRANGARAJ11@OKAXIS-623696 873176-UPI | C72: UPI | E72: 250 | F72: 78780
A73: 2026-08-25 | B73: UPI-00000030584912598-SHERIFFKMS-1@OKSBI -623767881819-GINGER | C73: UPI | E73: 260 | F73: 79040
A74: 2026-08-25 | B74: UPI-SUGANYA A-PAYTM.S225QIV@PTY-YESB0MCH UPI-128464594652-UPI | C74: UPI | D74: 50 | F74: 78990
A75: 2026-08-25 | B75: UPI-3556108000222-PMKAVI1989-3@OKHDFCBAN K-128469493990-UPI | C75: UPI | E75: 160 | F75: 79150
A76: 2026-08-25 | B76: UPI-7473342015-BHAVYAS.2207-2@OKHDFCBANK -128469741040-UPI | C76: UPI | E76: 80 | F76: 79230
A77: 2026-08-25 | B77: UPI-00000037900981145-SANTHANAKUMAR67881 @OKSBI-623778097426-UPI | C77: UPI | E77: 150 | F77: 79380
A78: 2026-08-25 | B78: UPI-041901000117659-9994477574@YESCRED-6 60321163502-PAIDVIACRED | C78: UPI | E78: 90 | F78: 79470
A79: 2026-08-25 | B79: UPI-75280100006202-VASANTHIARUL9496-2@OK AXIS-660376725788-UPI | C79: UPI | E79: 160 | F79: 79630
A80: 2026-08-25 | B80: UPI-JAGADESHT M-JAGADESHTM155@OKAXIS-KV BL0001739-660313230153-UPI | C80: UPI | E80: 5200 | F80: 84830
A81: 2026-08-25 | B81: UPI-53220004822812-BALAKRISHNANSASI1971- 5@OKICICI-660364929826-UPI | C81: UPI | E81: 200 | F81: 85030
A82: 2026-08-25 | B82: UPI-1326119002962-SUJATHAD945@OKAXIS-660 385707811-UPI | C82: UPI | E82: 80 | F82: 85110
...

Sheet Nagarajan-HDFC 6393
A1: Nagarajan (HDFC 6393) — All Transactions
A2: Extracted programmatically from the bank-provided PDF statement. Verified: sum of Withdrawal/Deposit columns matches the statement's own summary totals exactly.
A4: Date | B4: Narration | C4: Category | D4: Withdrawal (₹) | E4: Deposit (₹) | F4: Balance (₹)
A5: 2026-07-06 | B5: UPI-D SAMRAJ-SAMRAJD255@OKAXIS-INDB00000 21-618746266134-UPI | C5: UPI | E5: 800 | F5: 73776.25
A6: 2026-07-06 | B6: UPI-AJITHKUMAR S-AAJITHAJITH939@OKAXIS -IOBA0000124-618793157227-UPI | C6: UPI | E6: 2050 | F6: 75826.25
A7: 2026-07-06 | B7: UPI-RAJESH R-RAJESHPRIYAFEB04@OKSBI-SBI N0008608-618768853568-UPI | C7: UPI | E7: 4930 | F7: 80756.25
A8: 2026-07-06 | B8: UPI-ABDULMUTHALEP P-PS9605969@OKSBI-SBI N0001384-618772320001-UPI | C8: UPI | E8: 1950 | F8: 82706.25
A9: 2026-07-06 | B9: UPI-VMSVEGTABLES-8667811345@IOB-IOBA0 001747-618711905154-UPIFUNDTRANSFER | C9: UPI | E9: 18450 | F9: 101156.25
A10: 2026-07-06 | B10: UPI-DAISYRANI SUGUMAR-DAISYMANGUNI-3@OK ICICI-IOBA0001846-655324789784-UPI | C10: UPI | E10: 130 | F10: 101286.25
A11: 2026-07-07 | B11: UPI-VISHNUT M-VISHNUSHINCHAN@OKICICI-CN RB0000033-618805843360-UPI | C11: UPI | E11: 240 | F11: 101526.25
A12: 2026-07-07 | B12: EMI467832485CHQS46783248500410726467 832485 | C12: EMI | D12: 13319 | F12: 88207.25
A13: 2026-07-07 | B13: UPI-MRSUHAILAHAMED SIK-SHYSUHAIL@OKHDF CBANK-IDIB000K337-125921235237-UPI | C13: UPI | E13: 28200 | F13: 116407.25
A14: 2026-07-08 | B14: UPI-SMOHAN CO-M2037518@OKHDFCBANK-BARB0 VJMCOT-125931519920-UPI | C14: UPI | E14: 920 | F14: 117327.25
A15: 2026-07-11 | B15: UPI-SIVA SUBRAMANIAN-SIVASUBARAMANIAN16@ OKAXIS-CNRB0000000-619266513202-UPI | C15: UPI | E15: 220 | F15: 117547.25
A16: 2026-07-11 | B16: UPI-MSME FILINGS-MSMEFILINGS@OKHDFCBANK- HDFCBANKLIMITED *Closingbalanceincludesfundsearmarkedforholdandunclearedfunds Contentsofthisstatementwillbeconsideredcorrectifnoerrorisrepo | C16: UPI | D16: 1500 | F16: 116047.25
A17: 2026-07-13 | B17: UPI-INDHUMATHI-8870300492-3@AXL-ESMF0001 266-122085661581-PAYMENTFROMPHONE | C17: UPI | E17: 29500 | F17: 145547.25
A18: 2026-07-13 | B18: UPI-INDHUMATHI-8870300492-3@AXL-ESMF0001 266-621101201024-PAYMENTFROMPHONE | C18: UPI | E18: 3000 | F18: 148547.25
A19: 2026-07-13 | B19: UPI-MRSHEMALATHA G-HEMAJANANIMSC-1@OKIC ICI-IDIB000R023-656065411805-AUTOSALEA MT | C19: UPI | D19: 29500 | F19: 119047.25
A20: 2026-07-13 | B20: UPI-MRSHEMALATHA G-HEMAJANANIMSC-1@OKIC ICI-IDIB000R023-656047219878-AUTOSALEA MT | C20: UPI | D20: 3000 | F20: 116047.25
A21: 2026-07-14 | B21: UPI-ARUNKUMAR S-ARUNSAI060393@OKSBI-SBI N0000827-656171197724-CASH | C21: UPI | D21: 1500 | F21: 114547.25
A22: 2026-07-14 | B22: UPI-RAMACHANDRAN-PAYTM.S284E8T@PTY-YESB0 MCHUPI-126270425223-UPI | C22: UPI | D22: 150 | F22: 114397.25
A23: 2026-07-14 | B23: UPI-KARUPPUSAMY K-Q317395531@YBL-YESB0Y BLUPI-126270723337-UPI | C23: UPI | D23: 32 | F23: 114365.25
A24: 2026-07-14 | B24: UPI-CPMARUTHACHALAM AN-PAYTMQR6LT9FC@P TYS-YESB0PTMUPI-126280411024-UPI | C24: UPI | D24: 200 | F24: 114165.25
A25: 2026-07-14 | B25: UPI-JSYED RABIYAMMAL-SHAFIYASHAFIYA686@ OKICICI-TNSC0011700-619556998083-UPI | C25: UPI | E25: 2000 | F25: 116165.25
A26: 2026-07-14 | B26: UPI-DHANASEKAR KUMAR-Q543106160@YBL-YESB 0YBLUPI-126301984995-UPI | C26: UPI | D26: 70 | F26: 116095.25
A27: 2026-07-15 | B27: UPI-B MANIMEGALA-CCMAB.RASIKA@OKSBI-IOBA HDFCBANKLIMITED *Closingbalanceincludesfundsearmarkedforholdandunclearedfunds Contentsofthisstatementwillbeconsideredcorrectifnoerrorisrepo | C27: UPI | D27: 30 | F27: 116065.25
A28: 2026-07-15 | B28: UPI-CHANDRAN CHINNASAMY-ERCHANDRAN82-1@O KICICI-IOBA0000727-126327531679-RICE | C28: UPI | D28: 1650 | F28: 114415.25
A29: 2026-07-15 | B29: UPI-POOJAHARINIM-POOJAHARINI1234@OKSBI -KKBK0008659-126343903272-SORRYKARENT | C29: UPI | D29: 3500 | F29: 110915.25
A30: 2026-07-16 | B30: UPI-SHRIVARITRADERS-GPAY-11240888700@O KBIZAXIS-UTIB0000553-126364227188-GARLIC | C30: UPI | D30: 4685 | F30: 106230.25
A31: 2026-07-16 | B31: UPI-NOOR HASAN-PAYTM.S1LL34J@PTY-YESB0MC HUPI-126392567627-UPI | C31: UPI | D31: 30 | F31: 106200.25
A32: 2026-07-16 | B32: UPI-KRISHNAVENI-Q133286890@YBL-YESB0YBLU PI-126401795446-UPI | C32: UPI | D32: 20 | F32: 106180.25
A33: 2026-07-16 | B33: UPI-CHELLADURAI KARUPPA-GPAY-1219126229 4@OKBIZAXIS-UTIB0000553-126402383438-UPI | C33: UPI | D33: 40 | F33: 106140.25
A34: 2026-07-16 | B34: UPI-M VELMURUGAN-Q141268266@YBL-YESB0YBL UPI-126407219351-UPI | C34: UPI | D34: 50 | F34: 106090.25
A35: 2026-07-17 | B35: UPI-ABRAR KHAN-KHAN71828@OKSBI-SBIN0002 548-656419257942-UPI | C35: UPI | D35: 900 | F35: 105190.25
A36: 2026-07-17 | B36: UPI-SASI K-SWARNAKANNAN1@OKAXIS-BKID0008 200-656488370971-UPI | C36: UPI | E36: 1500 | F36: 106690.25
A37: 2026-07-17 | B37: UPI-JAYANNA-Q444639315@YBL-YESB0YBLUPI-1 26436895307-UPI | C37: UPI | D37: 100 | F37: 106590.25
A38: 2026-07-17 | B38: UPI-CPMARUTHACHALAM AN-PAYTMQR6LT9ES@P TYS-YESB0PTMUPI-126437199218-UPI | C38: UPI | D38: 200 | F38: 106390.25
A39: 2026-07-17 | B39: UPI-DMALAIPANDI-8220654668@AXL-HDFC0000 269-983924652535-PAYMENTFROMPHONE | C39: UPI | E39: 250 | F39: 106640.25
A40: 2026-07-18 | B40: UPI-SHRIVARITRADERS-GPAY-11240888700@O HDFCBANKLIMITED *Closingbalanceincludesfundsearmarkedforholdandunclearedfunds Contentsofthisstatementwillbeconsideredcorrectifnoerrorisreport | C40: UPI | D40: 6734 | F40: 99906.25
A41: 2026-07-18 | B41: UPI-RAVIKUMAR R-RAVIALAKKADA@OKSBI-SBIN 0008626-619924841229-UPI | C41: UPI | D41: 20 | F41: 99886.25
...

Sheet Nagarajan-ICICI 0314
A1: Nagarajan (ICICI 0314) — All Transactions
A2: Extracted programmatically from the bank-provided PDF statement. Verified: sum of Withdrawal/Deposit columns matches the statement's own summary totals exactly.
A4: Date | B4: Narration | C4: Category | D4: Withdrawal (₹) | E4: Deposit (₹) | F4: Balance (₹)
A5: 2026-07-06 | B5: saravanaku UPI/saravanaku/saravanakumar3/UPI/CANARA BAN/655330876480/ICIcd5780aa5a0140dba80402 14696fd73a/ SASGHPL RA | C5: UPI | D5: 50 | F5: 89971.03
A6: 2026-07-06 | B6: SASGHPL RA UPI/SASGHPL RA/q816918291@ybl/UPI/YES BANK L/655341277129/ICIef5a9cf1e30c4f48a48afd078e5 dba97/ PhonePe Bu | C6: UPI | D6: 218 | F6: 89753.03
A7: 2026-07-06 | B7: PhonePe Bu UPI/PhonePe Bu/phonepedeviceo/Payment fo/YES BANK L/655328194249/ICI6a327044f4124bd3a6a4e4552 322e829 hemajanani | C7: UPI | D7: 318 | F7: 89435.03
A8: 2026-07-06 | B8: hemajanani UPI/hemajanani/hemajananimsc-/UPI/INDIAN BAN/618750506474/ICIb317ab7fc8454a4792cf689 572b6cf41/ DHANASEKAR | C8: UPI | D8: 700 | F8: 88735.03
A9: 2026-07-06 | B9: DHANASEKAR UPI/DHANASEKAR/q525652580@ybl/UPI/YES BANK L/618729638003/ICIbf2721d343374f328b9e89bad c1957f9/ PhonePe Limited | C9: UPI | D9: 30 | F9: 88705.03
A10: 2026-07-07 | B10: PhonePe Limited NEFT-YESAP61884990391-PhonePe Limited-F09 M22UYYZ10YB2URED-002261100000025- YESB0000001 C P Maruth | C10: NEFT | E10: 1190 | F10: 89895.03
A11: 2026-07-07 | B11: C P Maruth UPI/C P Maruth/paytmqr6lt9f6@/UPI/YES BANK L/618853645238/ICI5e22247e08534049b167bb5f5 b5e42c0/ COVAI PACK | C11: UPI | D11: 200 | F11: 89695.03
A12: 2026-07-07 | B12: COVAI PACK UPI/COVAI PACK/paytmqr6yv9kb@/shop cover/YES BANK L/618891745441/ICI18900bab66d64ff8bdf0add93b bd76c3 MANIMARAN | C12: UPI | D12: 60 | F12: 89635.03
A13: 2026-07-07 | B13: MANIMARAN UPI/MANIMARAN/maranmani29-4@/ginger/AXIS BANK/618848344981/ICIb5a81d8db73940cda1ef5 75a56a70884/ BALAPRAKAS | C13: UPI | D13: 11000 | F13: 78635.03
A14: 2026-07-07 | B14: BALAPRAKAS UPI/BALAPRAKAS/9361075590@ybl/maintenanc/C ANARA BAN/618892069762/ICI94b5574b96474d3d8e33f3 dcd114241c MADHAVAN N | C14: UPI | D14: 800 | F14: 77835.03
A15: 2026-07-07 | B15: MADHAVAN N UPI/MADHAVAN N/gpay-122007105/UPI/AXIS BANK/655471115650/ICI09d27e93f353415387bac 2bc2141775e/ www.icici.bank.in Dial your Bank 1800-1080 Please call from your registere | C15: UPI | D15: 40 | F15: 77795.03
A16: 2026-07-07 | B16: DHANASEKAR UPI/DHANASEKAR/q525652580@ybl/UPI/YES BANK L/655406501622/ICI3e7cae087fe24940bb9f8ae3a0 6694fa/ VINITHKUMA | C16: UPI | D16: 40 | F16: 77755.03
A17: 2026-07-07 | B17: VINITHKUMA UPI/VINITHKUMA/paytm.s28qr3f@/UPI/YES BANK P/655427011909/ICI001630c0aed24103bb5dff6f8c 35476d/ PhonePe Limited | C17: UPI | D17: 80 | F17: 77675.03
A18: 2026-07-08 | B18: PhonePe Limited NEFT-YESAP61894542483-PhonePe Limited-F09 M22UYYZ10YB2URED-002261100000025- YESB0000001 KATHIRVEL | C18: NEFT | E18: 6505 | F18: 84180.03
A19: 2026-07-08 | B19: KATHIRVEL UPI/KATHIRVEL/pkvel123-1@oka/UPI/CANARA BAN/655544574745/ICI4684b6b69e254d5e9691da 57f2e8e988/ PhonePe Limited | C19: UPI | D19: 250 | F19: 83930.03
A20: 2026-07-09 | B20: PhonePe Limited NEFT-YESAP61904958547-PhonePe Limited-F09 M22UYYZ10YB2URED-002261100000025- YESB0000001 sofikulisl | C20: NEFT | E20: 2985 | F20: 86915.03
A21: 2026-07-09 | B21: sofikulisl UPI/sofikulisl/sofikulislam05/UPI/INDIAN BAN/619073325859/ICI23c51785fc414b04894fef9 58a949c37/ PhonePe Limited | C21: UPI | D21: 10900 | F21: 76015.03
A22: 2026-07-10 | B22: PhonePe Limited NEFT-YESAP61915061851-PhonePe Limited-F09 M22UYYZ10YB2URED-002261100000025- YESB0000001 PANDIYAN M | C22: NEFT | E22: 9105 | F22: 85120.03
A23: 2026-07-10 | B23: PANDIYAN M UPI/PANDIYAN M/9952794361-n48/UPI/TAMILNAD M/655723115941/ICIbb0fac59da954fb7903255e30 44142bd/ PAZHE RAND | C23: UPI | D23: 40 | F23: 85080.03
A24: 2026-07-10 | B24: PAZHE RAND UPI/PAZHE RAND/paytmqr6urnlc@/UPI/YES BANK L/655703106411/ICI89b6ca961cec43129370a5b50 e0446ef/ sofikulisl | C24: UPI | D24: 23 | F24: 85057.03
A25: 2026-07-10 | B25: sofikulisl UPI/sofikulisl/sofikulislam05/enji/INDIAN BAN/655734622956/ICI2613008cb3234e169d1bc5 656b16f39d/ RAJKUMAR C | C25: UPI | D25: 10500 | F25: 74557.03
A26: 2026-07-10 | B26: RAJKUMAR C UPI/RAJKUMAR C/paytmqr72sypy@/UPI/YES BANK L/655760944716/ICI5b9f025a34564433b826a31a6 b612969/ SREENIVASA | C26: UPI | D26: 12 | F26: 74545.03
A27: 2026-07-10 | B27: SREENIVASA UPI/SREENIVASA/gpay-121906071/UPI/AXIS BANK/655736042646/ICI13763f2b02f64ae6ad76b 288a3285aea/ Pandiyan M | C27: UPI | D27: 5 | F27: 74540.03
A28: 2026-07-10 | B28: Pandiyan M UPI/Pandiyan M/paytm.s28sl0k@/UPI/YES BANK P/655723263070/ICIe12bd0e9b54d459fb27a35857 a5b7783/ PhonePe Limited | C28: UPI | D28: 50 | F28: 74490.03
A29: 2026-07-11 | B29: PhonePe Limited NEFT-YESAP61921537849-PhonePe Limited-F09 M22UYYZ10YB2URED-002261100000025- YESB0000001 JAYAPRAKAS | C29: NEFT | E29: 12600 | F29: 87090.03
A30: 2026-07-11 | B30: JAYAPRAKAS UPI/JAYAPRAKAS/paytmqr2810050/UPI/YES BANK L/655887182678/ICIc3e51031bcc34c9d9b1f09807 bcefbd3/ www.icici.bank.in Dial your Bank 1800-1080 Please call from your register | C30: UPI | D30: 20 | F30: 87070.03
A31: 2026-07-11 | B31: MADHAVAN N UPI/MADHAVAN N/gpay-122007105/UPI/AXIS BANK/619274129607/ICI4be8433fa2364910a6b27 282109f4fb8/ PhonePe Limited | C31: UPI | D31: 50 | F31: 87020.03
A32: 2026-07-12 | B32: PhonePe Limited NEFT-YESAP61935557816-PhonePe Limited-F09 M22UYYZ10YB2URED-002261100000025- YESB0000001 COIMBATORE | C32: NEFT | E32: 5510 | F32: 92530.03
A33: 2026-07-12 | B33: COIMBATORE UPI/COIMBATORE/paytmqr6rayv6@/UPI/YES BANK L/619317989381/ICI08fd9ee1d2f5452f89fb93b4d8 d139fb/ RAJKUMAR C | C33: UPI | D33: 200 | F33: 92330.03
A34: 2026-07-12 | B34: RAJKUMAR C UPI/RAJKUMAR C/paytmqr72sypy@/UPI/YES BANK L/619344588510/ICI789c0b72396647e9a9ab5e636 be69c3d/ PhonePe Limited | C34: UPI | D34: 36 | F34: 92294.03
A35: 2026-07-13 | B35: PhonePe Limited NEFT-YESAP61945012265-PhonePe Limited-F09 M22UYYZ10YB2URED-002261100000025- YESB0000001 VELU | C35: NEFT | E35: 1685 | F35: 93979.03
A36: 2026-07-13 | B36: VELU UPI/VELU/vel.reachme@ok/UPI/UNION BANK/656088659402/ICI73e3522661b342b699ed0 b784a7a7fa8/ israeljarw | C36: UPI | D36: 80 | F36: 93899.03
A37: 2026-07-13 | B37: israeljarw UPI/israeljarw/israeljarwish-/UPI/ICICI Bank/656029158365/ICIba38f460e5c545308e3a1a 2b6ce1d413/ SHRI VARI | C37: UPI | D37: 110 | F37: 93789.03
A38: 2026-07-14 | B38: SHRI VARI UPI/SHRI VARI/gpay-112408887/rv garlic/AXIS BANK/619513218584/ICI41650d4810cc425986bd5 dc26d19e400/ PhonePe Limited | C38: UPI | D38: 3250 | F38: 90539.03
A39: 2026-07-15 | B39: PhonePe Limited NEFT-YESAP61964232060-PhonePe Limited-F09 M22UYYZ10YB2URED-002261100000025- YESB0000001 PhonePe Limited | C39: NEFT | E39: 3780 | F39: 94319.03
A40: 2026-07-16 | B40: PhonePe Limited NEFT-YESAP61974911891-PhonePe Limited-F09 M22UYYZ10YB2URED-002261100000025- YESB0000001 PhonePe Limited | C40: NEFT | E40: 7610 | F40: 101929.03
A41: 2026-07-17 | B41: PhonePe Limited NEFT-YESAP61986806371-PhonePe Limited-F09 M22UYYZ10YB2URED-002261100000025- YESB0000001 PhonePe Limited | C41: NEFT | E41: 8770 | F41: 110699.03
...
